<!--Creates a tendon fish based on Mike Yan Michelis' design. Adds a contact set between the head and the sliding block-->
<!-- Measures the force of the fish (from the thrust of its tail) via the FishTest.py script and the force sensor on the block-->
<!-- adds a realistic mass value to the bodies-->

<mujoco model="tendonFish">
    <option gravity="0 0 0" density="1000" viscosity="0.0013" integrator="implicitfast" timestep="0.001" iterations="100" solver="Newton" tolerance="1e-15" ls_tolerance="1e-9" noslip_tolerance="1e-9" o_solimp="0 0.01 0.01 0.1 2">
        <flag contact="enable"/>
        <!-- <flag override="enable"/> -->
    </option>

    <visual>
        <global offheight="2160" offwidth="3840"/>
        <rgba haze=".3 .3 .3 1"/>
    </visual>


    <!--add a mesh that pivots like the actual fishtank setup-->
    <!--imports meshes-->
    <asset>
        <texture type="skybox" builtin="gradient" rgb1="0.6 0.6 0.6" rgb2="0 0 0" width="512" height="512"/>
        <texture name="texplane" type="2d" builtin="checker" rgb1=".15 .2 .35" rgb2=".2 .3 .45" width="512" height="512" mark="cross" markrgb=".8 .8 .8"/>
        <material name="matplane" reflectance="0.3" texture="texplane" texrepeat="10 10" texuniform="true"/>
        <mesh name="tailMesh" file="C:\Users\15405\OneDrive\Desktop\Career\ETHZ\ETHZ Work\mujoco-3.3.2-windows-x86_64\model\mesh\tailV2.STL" scale="0.0015 0.0015 0.0025" />
        <mesh name="headMesh" file="C:\Users\15405\OneDrive\Desktop\Career\ETHZ\ETHZ Work\mujoco-3.3.2-windows-x86_64\model\mesh\headExternal.STL" scale="0.0015 0.0015 0.0025" />
        <mesh name="Tank" file="C:\Users\15405\OneDrive\Desktop\Career\ETHZ\ETHZ Work\mujoco-3.3.2-windows-x86_64\model\mesh\glassTank.STL" scale="0.0015 0.0015 0.0025" />
        <material name="acrylic" rgba="0.576470588235 0.694117647059 0.8 0.2"/>
        <material name="alu" reflectance="0.9" specular="0.9" shininess="0.9" rgba=".7 .7 .7 1"/>
        <material name="marker" rgba=".9 .4 .1 .5"/>
    </asset>

    
    <!--High damping and stifness values on tendon make it semi-rigid which is what is intended in the real-fish test-->
    <default>
        <joint type="hinge" pos="0 0 0" axis="0 0 1" range="-80 80" stiffness="0.65" damping="0.0"/>
        <geom fluidcoef="0.1 0.1 0.1 2.0 1.0" condim="1"/>
        <tendon width="0.005" rgba=".9 .6 .5 1" stiffness="60" damping="1"/>
    </default>
    

    <worldbody>
        <camera name="fixed" pos="0.4 -1.2 1.2" xyaxes="1 0 0 0 1 1"/>
        <camera name="fixedTop" pos="-0.75 0 1.5" xyaxes="0 -1 0 1 0 0.75"/>
        <camera name="fixedDiag" pos="0.75 -1 1" xyaxes="0.8 0.6 0 -0.4 0.5 0.75"/>
        <camera pos="0.625 -0.592 0.720" xyaxes="0.758 0.653 -0.000 -0.468 0.544 0.697"/>



        <geom name="floor" pos="0 0 -0.2" size="0 0 1" type="plane" material="matplane"/>
        <geom name="ceiling" pos="0 0 0.2" size="0 0 1" zaxis="0 0 -1" type="plane" rgba=".7 .1 .1 0"/>
        <light directional="true" diffuse=".8 .8 .8" specular=".2 .2 .2" pos="0 0 5" dir="0 0 -1"/>
        
        <!--creates a loadcell body-->
        <body name="slider_body" pos=".20 0 .45">
            <!--creates a geometry, not a joint, restricts all movement-->
            <geom type="box" size=".05 .05 .05" rgba="0 0 1 1" contype="1" mass=".1" conaffinity="1"/>
            <site name="ft_sensor" pos="0 0 0" rgba="1 1 1 1" size=".05 .05 .05" type="box" /> 
        </body>

        <body name="FishTank" pos="0 -.42 -.7">
            <geom name="TankMesh" type="mesh" mesh="Tank" pos="0 0 0" mass="0" contype="0" conaffinity="0" rgba="0.160784313725 0.588235294118 1 0.1"/>
        </body>

        <!--adds a slider range to keep the fish always propogating forward from its original com like in the simulation-->
        <!-- add a slider that keeps the head moving forward-->
        <body pos=".35 0 0">
            <joint name="headX" pos="0.02432519 0 0.00306519" type="slide" axis="1 0 0" stiffness="0" damping="0" range="-0.025669489880513867 0.003387345022720789"/>
            <site name="COM" pos="0.02432519 0 0.00306519" size="0.02" material="marker"/>

            <!-- realistic mass should be about .1 kg, had been .25 -->
            <geom name="head_mesh" type="mesh" mesh="headMesh" pos=".1 .105 .1" size="0.077 0.0025 0.05" material="acrylic" mass=".1" quat="0 0 .7071 -.7071" fluidshape="ellipsoid"  contype="1" conaffinity="1"  />
    

            <site name="marker0" pos="-0.077 0 0.05" size="0.005" material="marker"/>
            <site name="marker1" pos="0.065 0 0.05" size="0.005" material="marker"/>
            <site name="marker2" pos="0.1655 -0.0775 0.05" size="0.005" material="marker"/>
            <site name="marker3" pos="0.1655 0.0775 0.05" size="0.005" material="marker"/>
            <site name="bodyFin" pos="0.28 0 0.1" size="0.005" material="marker"/>

            <!--works with a python script that couplesthe hinge's movement with the fish's movement forward. So when the position is min x, it is backwards x degrees, and when it is at its forward most it is perpindicular range="-0.02432519 0.02432519"-->
            <body pos=".061 0 .25" name="ForceAmp" >
                <joint name="forceJoint" type="hinge" axis=" 0 1 0" pos="0 0 -.2" limited="true" stiffness="10000" damping="10000" range="-0.96 0"/>
                <site name="ForceCOM" pos=" 0 0 -.2" size=".02" material="alu" />
                <geom name="InitialHinge" type="cylinder" pos="0 0 0" size=".035 .2" material="alu" mass=".0005" fluidshape="ellipsoid" contype="1" conaffinity="1" />
                <geom name="sideHinge" type="cylinder" pos="-.05 0 .2" size=".035 .1" material="alu" mass=".00025" contype="1" conaffinity="1" quat=".7071 0 .7071 0" />
            </body>

            <!--<body pos=".061 0 .25" name="aestheticBeam" >
                <geom name="horizontalHinge" type="cylinder" pos=".05 0 .2" size=".055 .3" material="alu" mass="0"  quat=".7071 .7071 0 0" contype="0" conaffinity="0" />
            </body> -->
            
            
            <body pos="0.1655 0 0" name="motor" >
                <joint name="motor_rotate" type="hinge" axis="0 0 1" pos="0 0 0" limited="false" stiffness="0" damping="0"/>
                <geom name="motorSlider" type="cylinder" pos="0 0 0" size="0.0075 0.006" rgba=".1 .1 .1 1" density="1250" fluidshape="ellipsoid"/>
                <geom name="motorRods" type="box" pos="0 0 0" size="0.0075 0.05 0.001975" rgba=".1 .1 .1 1" density="1250" fluidshape="ellipsoid" contype="0" conaffinity="0"/>
                <site name="bodyLeft" pos="0 -0.035 0.00345" size="0.005" rgba=".9 .6 .5 .5"/>
                <site name="bodyRight" pos="0 0.035 0.00345" size="0.005" rgba=".9 .6 .5 .5"/>
            </body>

            <!-- <body pos="20 3.25 75" name="motor">
                <joint name="motor_rotate" type="hinge" axis="0 0 1" pos="0 0 0" limited="false" stiffness="0" damping="0"/>
                <geom name="motorSlider" type="cylinder" pos="0 0 0" size="3.5 5" rgba="0.59 0.8 1 .8" mass=".05" contype="1" conaffinity="1" />
                <geom name="motorRods" type="box" pos="0 0 0" size="1.5 14 1.5" rgba="0.59 0.8 1 .8" mass=".05" contype="1" conaffinity="1" density="1250"/>
                <site name="bodyLeft" pos="0 -14 1.5" size="3.75" rgba="0.031 0.509 0.96 .8"/>
                <site name="bodyRight" pos="0 14 1.5" size="3.75" rgba="0.031 0.509 0.96 .8"/>
            </body> -->
           
            
            <!--center frame realistic mass should be around .2 kg , divided by 5 joints should be .04 kg per joint-->
            <body pos="0.28500000000000003 0 0">
                <geom name="joint0" type="cylinder" pos="0 0 0" size="0.002 0.0376" rgba=".9 .2 .2 1" mass="0" contype="0" conaffinity="0"/>
                <joint name="joint0"/>
                <geom name="joint0-tail0" type="box" pos="0.0035 0 0" size="0.0035 0.0005 0.0375" rgba=".9 .9 .9 1" mass="0.001" fluidshape="ellipsoid" contype="0" conaffinity="0"/>
                <geom name="tail0" type="box" pos="0.014499999999999999 0 0" size="0.0075 0.0015 0.05" rgba=".5 .7 .9 1" density="1250" fluidshape="ellipsoid" contype="0" conaffinity="0"/>
                <site name="marker4" pos="0.014499999999999999 0 0.05" size="0.005" material="marker"/>

                <geom name="tail0left" type="box" pos="0.019 -0.02575 0" size="0.003 0.02925 0.007" rgba=".5 .7 .9 1" density="1250" fluidshape="ellipsoid" contype="0" conaffinity="0"/>
                <geom name="tail0right" type="box" pos="0.019 0.02575 0" size="0.003 0.02925 0.007" rgba=".5 .7 .9 1" density="1250" fluidshape="ellipsoid" contype="0" conaffinity="0"/>
                <site name="tail0left" pos="0.019 -0.045 0" size="0.004" rgba=".9 .6 .5 .5"/>
                <site name="tail0right" pos="0.019 0.045 0" size="0.004" rgba=".9 .6 .5 .5"/>

                <geom name="tail0-joint1" type="box" pos="0.02575 0 0" size="0.00375 0.0005 0.035" rgba=".9 .9 .9 1" mass="0.04" fluidshape="ellipsoid" contype="0" conaffinity="0"/>

                <body pos="0.0295 0 0">
                    <geom name="joint1" type="cylinder" pos="0 0 0" size="0.002 0.0351" rgba=".6 .1 .1 1" mass="0" contype="0" conaffinity="0"/>
                    <joint name="joint1"/>
                    <geom name="joint1-tail1" type="box" pos="0.00375 0 0" size="0.00375 0.0005 0.035" rgba=".9 .9 .9 1" mass="0.001" fluidshape="ellipsoid" contype="0" conaffinity="0"/>
                    <geom name="tail1" type="box" pos="0.015 0 0" size="0.0075 0.0015 0.0475" rgba=".5 .7 .9 1" density="1250" fluidshape="ellipsoid" contype="0" conaffinity="0"/>
                    <site name="marker5" pos="0.015 0 0.05" size="0.005" material="marker"/>

                    <geom name="tail1left" type="box" pos="0.0195 -0.02075 0" size="0.003 0.02425 0.007" rgba=".5 .7 .9 1" density="1250" fluidshape="ellipsoid" contype="0" conaffinity="0"/>
                    <geom name="tail1right" type="box" pos="0.0195 0.02075 0" size="0.003 0.02425 0.007" rgba=".5 .7 .9 1" density="1250" fluidshape="ellipsoid" contype="0" conaffinity="0"/>
                    <site name="tail1left" pos="0.0195 -0.035 0" size="0.004" rgba=".9 .6 .5 .5"/>
                    <site name="tail1right" pos="0.0195 0.035 0" size="0.004" rgba=".9 .6 .5 .5"/>

                    <geom name="tail1-joint2" type="box" pos="0.02675 0 0" size="0.00425 0.0005 0.0325" rgba=".9 .9 .9 1" mass="0.001" fluidshape="ellipsoid" contype="0" conaffinity="0"/>

                    <body pos="0.031 0 0">
                        <geom name="joint2" type="cylinder" pos="0 0 0" size="0.002 0.0326" rgba=".6 .1 .1 1" mass="0" contype="0" conaffinity="0"/>
                        <joint name="joint2"/>
                        <geom name="joint2-tail2" type="box" pos="0.00425 0 0" size="0.00425 0.0005 0.0325" rgba=".9 .9 .9 1" mass="0.001" fluidshape="ellipsoid" contype="0" conaffinity="0"/>
                        <geom name="tail2" type="box" pos="0.016 0 0" size="0.0075 0.0015 0.045" rgba=".5 .7 .9 1" density="1250" fluidshape="ellipsoid" contype="0" conaffinity="0"/>
                        <site name="marker6" pos="0.016 0 0.05" size="0.005" material="marker"/>

                        <geom name="tail2left" type="box" pos="0.0205 -0.01575 0" size="0.003 0.01925 0.007" rgba=".5 .7 .9 1" density="1250" fluidshape="ellipsoid" contype="0" conaffinity="0"/>
                        <geom name="tail2right" type="box" pos="0.0205 0.01575 0" size="0.003 0.01925 0.007" rgba=".5 .7 .9 1" density="1250" fluidshape="ellipsoid" contype="0" conaffinity="0"/>
                        <site name="tail2left" pos="0.0205 -0.025 0" size="0.004" rgba=".9 .6 .5 .5"/>
                        <site name="tail2right" pos="0.0205 0.025 0" size="0.004" rgba=".9 .6 .5 .5"/>

                        <geom name="tail2-joint3" type="box" pos="0.027 0 0" size="0.0035 0.0005 0.03" rgba=".9 .9 .9 1" mass="0.04" fluidshape="ellipsoid" contype="0" conaffinity="0"/>
                        
                        <body pos="0.0305 0 0">
                            <geom name="joint3" type="cylinder" pos="0 0 0" size="0.002 0.0301" rgba=".9 .2 .2 1" mass="0" contype="0" conaffinity="0"/>
                            <joint name="joint3"/>
                            <geom name="joint3-tail3" type="box" pos="0.0035 0 0" size="0.0035 0.0005 0.03" rgba=".9 .9 .9 1" mass="0.001" fluidshape="ellipsoid" contype="0" conaffinity="0"/>
                            <geom name="tail3" type="box" pos="0.014499999999999999 0 0" size="0.0075 0.0015 0.0425" rgba=".5 .7 .9 1" density="1250" fluidshape="ellipsoid" contype="0" conaffinity="0"/>
                            <site name="marker7" pos="0.014499999999999999 0 0.05" size="0.005" material="marker"/>

                            <geom name="tail3left" type="box" pos="0.019 -0.01075 0" size="0.003 0.01425 0.007" rgba=".5 .7 .9 1" density="1250" fluidshape="ellipsoid" contype="0" conaffinity="0"/>
                            <geom name="tail3right" type="box" pos="0.019 0.01075 0" size="0.003 0.01425 0.007" rgba=".5 .7 .9 1" density="1250" fluidshape="ellipsoid" contype="0" conaffinity="0"/>
                            <site name="tail3left" pos="0.019 -0.015 0" size="0.004" rgba=".9 .6 .5 .5"/>
                            <site name="tail3right" pos="0.019 0.015 0" size="0.004" rgba=".9 .6 .5 .5"/>

                            <geom name="tail3-joint4" type="box" pos="0.0235 0 0" size="0.0015 0.0005 0.0275" rgba=".9 .9 .9 1" mass="0.04" fluidshape="ellipsoid" contype="0" conaffinity="0"/>

                            <body pos="0.024999999999999998 0 0">
                                <geom name="joint4" type="cylinder" pos="0 0 0" size="0.0025 0.0276" rgba=".9 .2 .2 1" mass="0" contype="0" conaffinity="0"/>
                                <joint name="joint4"/>
                                <geom name="joint4-tail4" type="box" pos="0.0015 0 0" size="0.0015 0.0005 0.0275" rgba=".9 .9 .9 1" mass="0.001" fluidshape="ellipsoid" contype="0" conaffinity="0"/>
                                <geom name="tail4" type="box" pos="0.010499999999999999 0 0" size="0.0075 0.0015 0.04" rgba=".5 .7 .9 1" density="1250" fluidshape="ellipsoid" contype="0" conaffinity="0"/>
                                <site name="marker8" pos="0.010499999999999999 0 0.05" size="0.005" material="marker"/>

                                <geom name="tail4left" type="box" pos="0.015 -0.00575 0" size="0.003 0.00925 0.007" rgba=".5 .7 .9 1" density="1250" fluidshape="ellipsoid" contype="0" conaffinity="0"/>
                                <geom name="tail4right" type="box" pos="0.015 0.00575 0" size="0.003 0.00925 0.007" rgba=".5 .7 .9 1" density="1250" fluidshape="ellipsoid" contype="0" conaffinity="0"/>
                                <site name="tail4left" pos="0.015 -0.005 0" size="0.004" rgba=".9 .6 .5 .5"/>
                                <site name="tail4right" pos="0.015 0.005 0" size="0.004" rgba=".9 .6 .5 .5"/>

                                <body pos="0.02 0 0">
                                    <geom name="joint5" type="cylinder" pos="0 0 0" size="0.00175 0.0276" rgba=".9 .2 .2 1" mass="0" contype="0" conaffinity="0"/>
                                    <joint name="joint5"/>
                                    <geom name="joint5-tail5" type="box" pos="0.0015 0 0" size="0.0015 0.0005 0.0275" rgba=".9 .9 .9 1" mass="0.001" fluidshape="ellipsoid" contype="0" conaffinity="0"/>
                                    <geom name="tail5" type="box" pos="0.008 0 0" size="0.0055 0.0012 0.036" rgba=".5 .7 .9 1" density="1250" fluidshape="ellipsoid" contype="0" conaffinity="0"/>
                                    <site name="marker9" pos="0.010499999999999999 0 0.05" size="0.005" material="marker"/>

                                    <geom name="tail5left" type="box" pos="0.011 -0.00075 0" size="0.003 0.00425 0.007" rgba=".5 .7 .9 1" density="1250" fluidshape="ellipsoid" contype="0" conaffinity="0"/>
                                    <geom name="tail5right" type="box" pos="0.011 0.00075 0" size="0.003 0.00425 0.007" rgba=".5 .7 .9 1" density="1250" fluidshape="ellipsoid" contype="0" conaffinity="0"/>
                                    <site name="tail5left" pos="0.011 -0.005 0" size="0.004" rgba=".9 .6 .5 .5"/>
                                    <site name="tail5right" pos="0.011 0.005 0" size="0.004" rgba=".9 .6 .5 .5"/>

                                <!-- Tail Fin, realistic mass should be about .05 kg, was .15 kg -->
                                <geom name="finTail" type="mesh"  mesh="tailMesh" pos="-.190 -.00310 -.110" size="0.005 0.005 0.025" quat="0.7071 0.7071 0 0" rgba=".9 .9 .9 1" mass="0.05" fluidshape="ellipsoid" contype="0" conaffinity="0"/>
                                <site name="marker10" pos="0.025 .0085 -0.5" size="0.005" material="marker"/>

                                </body>
                            </body>
                        </body>
                    </body>
                </body>
            </body>
        </body>

    
    </worldbody>

    <!--tail organization-->
    <tendon>
        <spatial name="tendonLeft">
            <site site="bodyLeft"/>
            <site site="tail0left"/>
            <site site="tail1left"/>
            <site site="tail2left"/>
            <site site="tail3right"/>
            <site site="tail4right"/>
            <site site="tail5right"/>
        </spatial>
        <spatial name="tendonRight" >
            <site site="bodyRight"/>
            <site site="tail0right"/>
            <site site="tail1right"/>
            <site site="tail2right"/>
            <site site="tail3left"/>
            <site site="tail4left"/> 
            <site site="tail5left"/>           
        </spatial>
    </tendon>

    <!--creates actuator to control motor and to couple the forceamplifier. Measures the force with a sensor-->
    <actuator>
        <velocity name="motor" joint="motor_rotate" kv="100" ctrllimited="true" ctrlrange="-20 20" forcerange="-2.5 2.5"/>
         <position name="force_actuator" joint="forceJoint" kp="500"/>
    </actuator>

    <sensor>
        <force name = "force" site="ft_sensor" />
	</sensor>

</mujoco>